[2017-10-30 14:15:20 +0100] [11094] [INFO] Handling signal: term
[2017-10-30 14:15:21 +0100] [11097] [INFO] Worker exiting (pid: 11097)
[2017-10-30 14:15:21 +0100] [11094] [INFO] Shutting down: Master
[2017-10-30 14:15:25 +0100] [11771] [INFO] Starting gunicorn 19.7.1
[2017-10-30 14:15:25 +0100] [11771] [INFO] Listening at: http://0.0.0.0:5000 (11771)
[2017-10-30 14:15:25 +0100] [11771] [INFO] Using worker: eventlet
[2017-10-30 14:15:25 +0100] [11774] [INFO] Booting worker with pid: 11774
[2017-10-30 14:29:30 +0100] [11771] [INFO] Handling signal: term
[2017-10-30 14:29:31 +0100] [11774] [INFO] Worker exiting (pid: 11774)
[2017-10-30 14:29:31 +0100] [11771] [INFO] Shutting down: Master
[2017-10-30 14:29:35 +0100] [12043] [INFO] Starting gunicorn 19.7.1
[2017-10-30 14:29:35 +0100] [12043] [INFO] Listening at: http://0.0.0.0:5000 (12043)
[2017-10-30 14:29:35 +0100] [12043] [INFO] Using worker: eventlet
[2017-10-30 14:29:35 +0100] [12046] [INFO] Booting worker with pid: 12046
[2017-10-30 14:31:14 +0100] [12043] [INFO] Handling signal: term
[2017-10-30 14:31:15 +0100] [12046] [INFO] Worker exiting (pid: 12046)
[2017-10-30 14:31:16 +0100] [12043] [INFO] Shutting down: Master
[2017-10-30 14:31:20 +0100] [12079] [INFO] Starting gunicorn 19.7.1
[2017-10-30 14:31:20 +0100] [12079] [INFO] Listening at: http://0.0.0.0:5000 (12079)
[2017-10-30 14:31:20 +0100] [12079] [INFO] Using worker: eventlet
[2017-10-30 14:31:20 +0100] [12082] [INFO] Booting worker with pid: 12082
[2017-10-30 14:32:46 +0100] [12079] [INFO] Handling signal: term
[2017-10-30 14:32:46 +0100] [12082] [INFO] Worker exiting (pid: 12082)
[2017-10-30 14:32:47 +0100] [12079] [INFO] Shutting down: Master
[2017-10-30 14:32:51 +0100] [12113] [INFO] Starting gunicorn 19.7.1
[2017-10-30 14:32:51 +0100] [12113] [INFO] Listening at: http://0.0.0.0:5000 (12113)
[2017-10-30 14:32:51 +0100] [12113] [INFO] Using worker: eventlet
[2017-10-30 14:32:51 +0100] [12117] [INFO] Booting worker with pid: 12117
[2017-10-30 14:32:51 +0100] [12117] [ERROR] invalid syntax (gastrowalogger.py, line 940)
Traceback (most recent call last):
  File "/home/pi/gastrowalogger_env/lib/python3.4/site-packages/gunicorn/workers/base.py", line 135, in load_wsgi
    self.wsgi = self.app.wsgi()
  File "/home/pi/gastrowalogger_env/lib/python3.4/site-packages/gunicorn/app/base.py", line 67, in wsgi
    self.callable = self.load()
  File "/home/pi/gastrowalogger_env/lib/python3.4/site-packages/gunicorn/app/wsgiapp.py", line 65, in load
    return self.load_wsgiapp()
  File "/home/pi/gastrowalogger_env/lib/python3.4/site-packages/gunicorn/app/wsgiapp.py", line 52, in load_wsgiapp
    return util.import_app(self.app_uri)
  File "/home/pi/gastrowalogger_env/lib/python3.4/site-packages/gunicorn/util.py", line 352, in import_app
    __import__(module)
  File "/home/pi/gastrowalogger_env/wsgi.py", line 1, in <module>
    from gastrowalogger import app as application
  File "/home/pi/gastrowalogger_env/gastrowalogger.py", line 940
    datum_zeit_bis = tz.fromutc(datetime.utcfromtimestamp((zeitpunkt_bis - 1)))
                 ^
SyntaxError: invalid syntax
[2017-10-30 14:32:51 +0100] [12117] [ERROR] Exception in worker process
Traceback (most recent call last):
  File "/home/pi/gastrowalogger_env/lib/python3.4/site-packages/gunicorn/workers/base.py", line 135, in load_wsgi
    self.wsgi = self.app.wsgi()
  File "/home/pi/gastrowalogger_env/lib/python3.4/site-packages/gunicorn/app/base.py", line 67, in wsgi
    self.callable = self.load()
  File "/home/pi/gastrowalogger_env/lib/python3.4/site-packages/gunicorn/app/wsgiapp.py", line 65, in load
    return self.load_wsgiapp()
  File "/home/pi/gastrowalogger_env/lib/python3.4/site-packages/gunicorn/app/wsgiapp.py", line 52, in load_wsgiapp
    return util.import_app(self.app_uri)
  File "/home/pi/gastrowalogger_env/lib/python3.4/site-packages/gunicorn/util.py", line 352, in import_app
    __import__(module)
  File "/home/pi/gastrowalogger_env/wsgi.py", line 1, in <module>
    from gastrowalogger import app as application
  File "/home/pi/gastrowalogger_env/gastrowalogger.py", line 940
    datum_zeit_bis = tz.fromutc(datetime.utcfromtimestamp((zeitpunkt_bis - 1)))
                 ^
SyntaxError: invalid syntax

During handling of the above exception, another exception occurred:

Traceback (most recent call last):
  File "/home/pi/gastrowalogger_env/lib/python3.4/site-packages/gunicorn/arbiter.py", line 578, in spawn_worker
    worker.init_process()
  File "/home/pi/gastrowalogger_env/lib/python3.4/site-packages/gunicorn/workers/geventlet.py", line 103, in init_process
    super(EventletWorker, self).init_process()
  File "/home/pi/gastrowalogger_env/lib/python3.4/site-packages/gunicorn/workers/base.py", line 126, in init_process
    self.load_wsgi()
  File "/home/pi/gastrowalogger_env/lib/python3.4/site-packages/gunicorn/workers/base.py", line 148, in load_wsgi
    self.reloader.add_extra_file(exc_val.filename)
AttributeError: 'NoneType' object has no attribute 'add_extra_file'
[2017-10-30 14:32:51 +0100] [12117] [INFO] Worker exiting (pid: 12117)
[2017-10-30 14:32:51 +0100] [12113] [INFO] Shutting down: Master
[2017-10-30 14:32:51 +0100] [12113] [INFO] Reason: Worker failed to boot.
[2017-10-30 14:33:17 +0100] [12164] [INFO] Starting gunicorn 19.7.1
[2017-10-30 14:33:17 +0100] [12164] [INFO] Listening at: http://0.0.0.0:5000 (12164)
[2017-10-30 14:33:17 +0100] [12164] [INFO] Using worker: eventlet
[2017-10-30 14:33:17 +0100] [12167] [INFO] Booting worker with pid: 12167
[2017-10-30 14:33:22,450] ERROR in app: Exception on /charts/_get_chart [POST]
Traceback (most recent call last):
  File "/home/pi/gastrowalogger_env/lib/python3.4/site-packages/flask/app.py", line 1982, in wsgi_app
    response = self.full_dispatch_request()
  File "/home/pi/gastrowalogger_env/lib/python3.4/site-packages/flask/app.py", line 1614, in full_dispatch_request
    rv = self.handle_user_exception(e)
  File "/home/pi/gastrowalogger_env/lib/python3.4/site-packages/flask/app.py", line 1517, in handle_user_exception
    reraise(exc_type, exc_value, tb)
  File "/home/pi/gastrowalogger_env/lib/python3.4/site-packages/flask/_compat.py", line 33, in reraise
    raise value
  File "/home/pi/gastrowalogger_env/lib/python3.4/site-packages/flask/app.py", line 1612, in full_dispatch_request
    rv = self.dispatch_request()
  File "/home/pi/gastrowalogger_env/lib/python3.4/site-packages/flask/app.py", line 1598, in dispatch_request
    return self.view_functions[rule.endpoint](**req.view_args)
  File "/home/pi/gastrowalogger_env/gastrowalogger.py", line 939, in calculate_chart
    datum_zeit_von = tz.fromutc(tz.normalize(datetime.utcfromtimestamp((zeitpunkt_bis-resolution))))
  File "/home/pi/gastrowalogger_env/lib/python3.4/site-packages/pytz/tzinfo.py", line 235, in normalize
    raise ValueError('Naive time - no tzinfo set')
ValueError: Naive time - no tzinfo set
[2017-10-30 14:33:22,707] ERROR in app: Exception on /charts/_get_chart [POST]
Traceback (most recent call last):
  File "/home/pi/gastrowalogger_env/lib/python3.4/site-packages/flask/app.py", line 1982, in wsgi_app
    response = self.full_dispatch_request()
  File "/home/pi/gastrowalogger_env/lib/python3.4/site-packages/flask/app.py", line 1614, in full_dispatch_request
    rv = self.handle_user_exception(e)
  File "/home/pi/gastrowalogger_env/lib/python3.4/site-packages/flask/app.py", line 1517, in handle_user_exception
    reraise(exc_type, exc_value, tb)
  File "/home/pi/gastrowalogger_env/lib/python3.4/site-packages/flask/_compat.py", line 33, in reraise
    raise value
  File "/home/pi/gastrowalogger_env/lib/python3.4/site-packages/flask/app.py", line 1612, in full_dispatch_request
    rv = self.dispatch_request()
  File "/home/pi/gastrowalogger_env/lib/python3.4/site-packages/flask/app.py", line 1598, in dispatch_request
    return self.view_functions[rule.endpoint](**req.view_args)
  File "/home/pi/gastrowalogger_env/gastrowalogger.py", line 939, in calculate_chart
    datum_zeit_von = tz.fromutc(tz.normalize(datetime.utcfromtimestamp((zeitpunkt_bis-resolution))))
  File "/home/pi/gastrowalogger_env/lib/python3.4/site-packages/pytz/tzinfo.py", line 235, in normalize
    raise ValueError('Naive time - no tzinfo set')
ValueError: Naive time - no tzinfo set
[2017-10-30 14:33:25,210] ERROR in app: Exception on /charts/_get_chart [POST]
Traceback (most recent call last):
  File "/home/pi/gastrowalogger_env/lib/python3.4/site-packages/flask/app.py", line 1982, in wsgi_app
    response = self.full_dispatch_request()
  File "/home/pi/gastrowalogger_env/lib/python3.4/site-packages/flask/app.py", line 1614, in full_dispatch_request
    rv = self.handle_user_exception(e)
  File "/home/pi/gastrowalogger_env/lib/python3.4/site-packages/flask/app.py", line 1517, in handle_user_exception
    reraise(exc_type, exc_value, tb)
  File "/home/pi/gastrowalogger_env/lib/python3.4/site-packages/flask/_compat.py", line 33, in reraise
    raise value
  File "/home/pi/gastrowalogger_env/lib/python3.4/site-packages/flask/app.py", line 1612, in full_dispatch_request
    rv = self.dispatch_request()
  File "/home/pi/gastrowalogger_env/lib/python3.4/site-packages/flask/app.py", line 1598, in dispatch_request
    return self.view_functions[rule.endpoint](**req.view_args)
  File "/home/pi/gastrowalogger_env/gastrowalogger.py", line 939, in calculate_chart
    datum_zeit_von = tz.fromutc(tz.normalize(datetime.utcfromtimestamp((zeitpunkt_bis-resolution))))
  File "/home/pi/gastrowalogger_env/lib/python3.4/site-packages/pytz/tzinfo.py", line 235, in normalize
    raise ValueError('Naive time - no tzinfo set')
ValueError: Naive time - no tzinfo set
[2017-10-30 14:33:25,435] ERROR in app: Exception on /charts/_get_chart [POST]
Traceback (most recent call last):
  File "/home/pi/gastrowalogger_env/lib/python3.4/site-packages/flask/app.py", line 1982, in wsgi_app
    response = self.full_dispatch_request()
  File "/home/pi/gastrowalogger_env/lib/python3.4/site-packages/flask/app.py", line 1614, in full_dispatch_request
    rv = self.handle_user_exception(e)
  File "/home/pi/gastrowalogger_env/lib/python3.4/site-packages/flask/app.py", line 1517, in handle_user_exception
    reraise(exc_type, exc_value, tb)
  File "/home/pi/gastrowalogger_env/lib/python3.4/site-packages/flask/_compat.py", line 33, in reraise
    raise value
  File "/home/pi/gastrowalogger_env/lib/python3.4/site-packages/flask/app.py", line 1612, in full_dispatch_request
    rv = self.dispatch_request()
  File "/home/pi/gastrowalogger_env/lib/python3.4/site-packages/flask/app.py", line 1598, in dispatch_request
    return self.view_functions[rule.endpoint](**req.view_args)
  File "/home/pi/gastrowalogger_env/gastrowalogger.py", line 939, in calculate_chart
    datum_zeit_von = tz.fromutc(tz.normalize(datetime.utcfromtimestamp((zeitpunkt_bis-resolution))))
  File "/home/pi/gastrowalogger_env/lib/python3.4/site-packages/pytz/tzinfo.py", line 235, in normalize
    raise ValueError('Naive time - no tzinfo set')
ValueError: Naive time - no tzinfo set
[2017-10-30 15:59:11,551] ERROR in app: Exception on /charts/_get_chart [POST]
Traceback (most recent call last):
  File "/home/pi/gastrowalogger_env/lib/python3.4/site-packages/flask/app.py", line 1982, in wsgi_app
    response = self.full_dispatch_request()
  File "/home/pi/gastrowalogger_env/lib/python3.4/site-packages/flask/app.py", line 1614, in full_dispatch_request
    rv = self.handle_user_exception(e)
  File "/home/pi/gastrowalogger_env/lib/python3.4/site-packages/flask/app.py", line 1517, in handle_user_exception
    reraise(exc_type, exc_value, tb)
  File "/home/pi/gastrowalogger_env/lib/python3.4/site-packages/flask/_compat.py", line 33, in reraise
    raise value
  File "/home/pi/gastrowalogger_env/lib/python3.4/site-packages/flask/app.py", line 1612, in full_dispatch_request
    rv = self.dispatch_request()
  File "/home/pi/gastrowalogger_env/lib/python3.4/site-packages/flask/app.py", line 1598, in dispatch_request
    return self.view_functions[rule.endpoint](**req.view_args)
  File "/home/pi/gastrowalogger_env/gastrowalogger.py", line 939, in calculate_chart
    datum_zeit_von = tz.fromutc(datetime.utcfromtimestamp((zeitpunkt_bis-resolution)))
  File "/home/pi/gastrowalogger_env/lib/python3.4/site-packages/pytz/tzinfo.py", line 235, in normalize
    raise ValueError('Naive time - no tzinfo set')
ValueError: Naive time - no tzinfo set
[2017-10-30 15:59:28 +0100] [12164] [INFO] Handling signal: term
[2017-10-30 15:59:28 +0100] [12167] [INFO] Worker exiting (pid: 12167)
[2017-10-30 15:59:28 +0100] [12164] [INFO] Shutting down: Master
[2017-10-30 15:59:32 +0100] [13739] [INFO] Starting gunicorn 19.7.1
[2017-10-30 15:59:32 +0100] [13739] [INFO] Listening at: http://0.0.0.0:5000 (13739)
[2017-10-30 15:59:32 +0100] [13739] [INFO] Using worker: eventlet
[2017-10-30 15:59:32 +0100] [13742] [INFO] Booting worker with pid: 13742
[2017-10-30 16:07:41 +0100] [13739] [INFO] Handling signal: term
[2017-10-30 16:07:41 +0100] [13742] [INFO] Worker exiting (pid: 13742)
[2017-10-30 16:07:42 +0100] [13739] [INFO] Shutting down: Master
[2017-10-30 16:07:46 +0100] [13907] [INFO] Starting gunicorn 19.7.1
[2017-10-30 16:07:46 +0100] [13907] [INFO] Listening at: http://0.0.0.0:5000 (13907)
[2017-10-30 16:07:46 +0100] [13907] [INFO] Using worker: eventlet
[2017-10-30 16:07:46 +0100] [13910] [INFO] Booting worker with pid: 13910
[2017-10-30 16:08:02 +0100] [13907] [INFO] Handling signal: term
[2017-10-30 16:08:02 +0100] [13910] [INFO] Worker exiting (pid: 13910)
[2017-10-30 16:08:03 +0100] [13907] [INFO] Shutting down: Master
[2017-10-30 16:08:07 +0100] [13931] [INFO] Starting gunicorn 19.7.1
[2017-10-30 16:08:07 +0100] [13931] [INFO] Listening at: http://0.0.0.0:5000 (13931)
[2017-10-30 16:08:07 +0100] [13931] [INFO] Using worker: eventlet
[2017-10-30 16:08:07 +0100] [13935] [INFO] Booting worker with pid: 13935
[2017-10-31 13:46:50 +0100] [13931] [INFO] Handling signal: term
[2017-10-31 13:46:50 +0100] [13935] [INFO] Worker exiting (pid: 13935)
[2017-10-31 13:46:50 +0100] [13931] [INFO] Shutting down: Master
[2017-10-31 13:46:56 +0100] [2620] [INFO] Starting gunicorn 19.7.1
[2017-10-31 13:46:56 +0100] [2620] [INFO] Listening at: http://0.0.0.0:5000 (2620)
[2017-10-31 13:46:56 +0100] [2620] [INFO] Using worker: eventlet
[2017-10-31 13:46:56 +0100] [2639] [INFO] Booting worker with pid: 2639
[2017-10-31 13:46:59 +0100] [2639] [ERROR] Exception in worker process
Traceback (most recent call last):
  File "/home/pi/gastrowalogger_env/lib/python3.4/site-packages/gunicorn/arbiter.py", line 578, in spawn_worker
    worker.init_process()
  File "/home/pi/gastrowalogger_env/lib/python3.4/site-packages/gunicorn/workers/geventlet.py", line 103, in init_process
    super(EventletWorker, self).init_process()
  File "/home/pi/gastrowalogger_env/lib/python3.4/site-packages/gunicorn/workers/base.py", line 126, in init_process
    self.load_wsgi()
  File "/home/pi/gastrowalogger_env/lib/python3.4/site-packages/gunicorn/workers/base.py", line 135, in load_wsgi
    self.wsgi = self.app.wsgi()
  File "/home/pi/gastrowalogger_env/lib/python3.4/site-packages/gunicorn/app/base.py", line 67, in wsgi
    self.callable = self.load()
  File "/home/pi/gastrowalogger_env/lib/python3.4/site-packages/gunicorn/app/wsgiapp.py", line 65, in load
    return self.load_wsgiapp()
  File "/home/pi/gastrowalogger_env/lib/python3.4/site-packages/gunicorn/app/wsgiapp.py", line 52, in load_wsgiapp
    return util.import_app(self.app_uri)
  File "/home/pi/gastrowalogger_env/lib/python3.4/site-packages/gunicorn/util.py", line 352, in import_app
    __import__(module)
  File "/home/pi/gastrowalogger_env/wsgi.py", line 1, in <module>
    from gastrowalogger import app as application
  File "/home/pi/gastrowalogger_env/gastrowalogger.py", line 20, in <module>
    from matplotlib.dates import seconds
ImportError: No module named 'matplotlib'
[2017-10-31 13:46:59 +0100] [2639] [INFO] Worker exiting (pid: 2639)
[2017-10-31 13:47:00 +0100] [2620] [INFO] Shutting down: Master
[2017-10-31 13:47:00 +0100] [2620] [INFO] Reason: Worker failed to boot.
[2017-10-31 13:47:40 +0100] [2864] [INFO] Starting gunicorn 19.7.1
[2017-10-31 13:47:40 +0100] [2864] [INFO] Listening at: http://0.0.0.0:5000 (2864)
[2017-10-31 13:47:40 +0100] [2864] [INFO] Using worker: eventlet
[2017-10-31 13:47:40 +0100] [2874] [INFO] Booting worker with pid: 2874
[2017-10-31 13:47:45,209] ERROR in app: Exception on /charts/_get_chart [POST]
Traceback (most recent call last):
  File "/home/pi/gastrowalogger_env/lib/python3.4/site-packages/flask/app.py", line 1982, in wsgi_app
    response = self.full_dispatch_request()
  File "/home/pi/gastrowalogger_env/lib/python3.4/site-packages/flask/app.py", line 1614, in full_dispatch_request
    rv = self.handle_user_exception(e)
  File "/home/pi/gastrowalogger_env/lib/python3.4/site-packages/flask/app.py", line 1517, in handle_user_exception
    reraise(exc_type, exc_value, tb)
  File "/home/pi/gastrowalogger_env/lib/python3.4/site-packages/flask/_compat.py", line 33, in reraise
    raise value
  File "/home/pi/gastrowalogger_env/lib/python3.4/site-packages/flask/app.py", line 1612, in full_dispatch_request
    rv = self.dispatch_request()
  File "/home/pi/gastrowalogger_env/lib/python3.4/site-packages/flask/app.py", line 1598, in dispatch_request
    return self.view_functions[rule.endpoint](**req.view_args)
  File "/home/pi/gastrowalogger_env/gastrowalogger.py", line 563, in calculate_chart
    datum_zeit_von = tz.fromutc(datetime.utcfromtimestamp((zeitpunkt_bis-resolution)))
TypeError: unsupported operand type(s) for -: 'datetime.datetime' and 'int'
[2017-10-31 13:47:45,453] ERROR in app: Exception on /charts/_get_chart [POST]
Traceback (most recent call last):
  File "/home/pi/gastrowalogger_env/lib/python3.4/site-packages/flask/app.py", line 1982, in wsgi_app
    response = self.full_dispatch_request()
  File "/home/pi/gastrowalogger_env/lib/python3.4/site-packages/flask/app.py", line 1614, in full_dispatch_request
    rv = self.handle_user_exception(e)
  File "/home/pi/gastrowalogger_env/lib/python3.4/site-packages/flask/app.py", line 1517, in handle_user_exception
    reraise(exc_type, exc_value, tb)
  File "/home/pi/gastrowalogger_env/lib/python3.4/site-packages/flask/_compat.py", line 33, in reraise
    raise value
  File "/home/pi/gastrowalogger_env/lib/python3.4/site-packages/flask/app.py", line 1612, in full_dispatch_request
    rv = self.dispatch_request()
  File "/home/pi/gastrowalogger_env/lib/python3.4/site-packages/flask/app.py", line 1598, in dispatch_request
    return self.view_functions[rule.endpoint](**req.view_args)
  File "/home/pi/gastrowalogger_env/gastrowalogger.py", line 563, in calculate_chart
    datum_zeit_von = tz.fromutc(datetime.utcfromtimestamp((zeitpunkt_bis-resolution)))
TypeError: unsupported operand type(s) for -: 'datetime.datetime' and 'int'
[2017-10-31 13:50:20 +0100] [2864] [INFO] Handling signal: term
[2017-10-31 13:50:21 +0100] [2874] [INFO] Worker exiting (pid: 2874)
[2017-10-31 13:50:21 +0100] [2864] [INFO] Shutting down: Master
[2017-10-31 13:50:26 +0100] [3658] [INFO] Starting gunicorn 19.7.1
[2017-10-31 13:50:26 +0100] [3658] [INFO] Listening at: http://0.0.0.0:5000 (3658)
[2017-10-31 13:50:26 +0100] [3658] [INFO] Using worker: eventlet
[2017-10-31 13:50:26 +0100] [3678] [INFO] Booting worker with pid: 3678
[2017-10-31 13:50:31,895] ERROR in app: Exception on /charts/_get_chart [POST]
Traceback (most recent call last):
  File "/home/pi/gastrowalogger_env/lib/python3.4/site-packages/flask/app.py", line 1982, in wsgi_app
    response = self.full_dispatch_request()
  File "/home/pi/gastrowalogger_env/lib/python3.4/site-packages/flask/app.py", line 1614, in full_dispatch_request
    rv = self.handle_user_exception(e)
  File "/home/pi/gastrowalogger_env/lib/python3.4/site-packages/flask/app.py", line 1517, in handle_user_exception
    reraise(exc_type, exc_value, tb)
  File "/home/pi/gastrowalogger_env/lib/python3.4/site-packages/flask/_compat.py", line 33, in reraise
    raise value
  File "/home/pi/gastrowalogger_env/lib/python3.4/site-packages/flask/app.py", line 1612, in full_dispatch_request
    rv = self.dispatch_request()
  File "/home/pi/gastrowalogger_env/lib/python3.4/site-packages/flask/app.py", line 1598, in dispatch_request
    return self.view_functions[rule.endpoint](**req.view_args)
  File "/home/pi/gastrowalogger_env/gastrowalogger.py", line 571, in calculate_chart
    if (current_date < zeitpunkt_bis):
TypeError: can't compare offset-naive and offset-aware datetimes
[2017-10-31 13:50:32,124] ERROR in app: Exception on /charts/_get_chart [POST]
Traceback (most recent call last):
  File "/home/pi/gastrowalogger_env/lib/python3.4/site-packages/flask/app.py", line 1982, in wsgi_app
    response = self.full_dispatch_request()
  File "/home/pi/gastrowalogger_env/lib/python3.4/site-packages/flask/app.py", line 1614, in full_dispatch_request
    rv = self.handle_user_exception(e)
  File "/home/pi/gastrowalogger_env/lib/python3.4/site-packages/flask/app.py", line 1517, in handle_user_exception
    reraise(exc_type, exc_value, tb)
  File "/home/pi/gastrowalogger_env/lib/python3.4/site-packages/flask/_compat.py", line 33, in reraise
    raise value
  File "/home/pi/gastrowalogger_env/lib/python3.4/site-packages/flask/app.py", line 1612, in full_dispatch_request
    rv = self.dispatch_request()
  File "/home/pi/gastrowalogger_env/lib/python3.4/site-packages/flask/app.py", line 1598, in dispatch_request
    return self.view_functions[rule.endpoint](**req.view_args)
  File "/home/pi/gastrowalogger_env/gastrowalogger.py", line 571, in calculate_chart
    if (current_date < zeitpunkt_bis):
TypeError: can't compare offset-naive and offset-aware datetimes
[2017-10-31 13:52:15 +0100] [3658] [INFO] Handling signal: term
[2017-10-31 13:52:16 +0100] [3678] [INFO] Worker exiting (pid: 3678)
[2017-10-31 13:52:16 +0100] [3658] [INFO] Shutting down: Master
[2017-10-31 13:52:20 +0100] [4030] [INFO] Starting gunicorn 19.7.1
[2017-10-31 13:52:20 +0100] [4030] [INFO] Listening at: http://0.0.0.0:5000 (4030)
[2017-10-31 13:52:20 +0100] [4030] [INFO] Using worker: eventlet
[2017-10-31 13:52:20 +0100] [4039] [INFO] Booting worker with pid: 4039
[2017-10-31 13:52:26,135] ERROR in app: Exception on /charts/_get_chart [POST]
Traceback (most recent call last):
  File "/home/pi/gastrowalogger_env/lib/python3.4/site-packages/flask/app.py", line 1982, in wsgi_app
    response = self.full_dispatch_request()
  File "/home/pi/gastrowalogger_env/lib/python3.4/site-packages/flask/app.py", line 1614, in full_dispatch_request
    rv = self.handle_user_exception(e)
  File "/home/pi/gastrowalogger_env/lib/python3.4/site-packages/flask/app.py", line 1517, in handle_user_exception
    reraise(exc_type, exc_value, tb)
  File "/home/pi/gastrowalogger_env/lib/python3.4/site-packages/flask/_compat.py", line 33, in reraise
    raise value
  File "/home/pi/gastrowalogger_env/lib/python3.4/site-packages/flask/app.py", line 1612, in full_dispatch_request
    rv = self.dispatch_request()
  File "/home/pi/gastrowalogger_env/lib/python3.4/site-packages/flask/app.py", line 1598, in dispatch_request
    return self.view_functions[rule.endpoint](**req.view_args)
  File "/home/pi/gastrowalogger_env/gastrowalogger.py", line 590, in calculate_chart
    zeitpunkt_bis += timedelta.seconds(resolution)
TypeError: 'member_descriptor' object is not callable
[2017-10-31 13:52:26,373] ERROR in app: Exception on /charts/_get_chart [POST]
Traceback (most recent call last):
  File "/home/pi/gastrowalogger_env/lib/python3.4/site-packages/flask/app.py", line 1982, in wsgi_app
    response = self.full_dispatch_request()
  File "/home/pi/gastrowalogger_env/lib/python3.4/site-packages/flask/app.py", line 1614, in full_dispatch_request
    rv = self.handle_user_exception(e)
  File "/home/pi/gastrowalogger_env/lib/python3.4/site-packages/flask/app.py", line 1517, in handle_user_exception
    reraise(exc_type, exc_value, tb)
  File "/home/pi/gastrowalogger_env/lib/python3.4/site-packages/flask/_compat.py", line 33, in reraise
    raise value
  File "/home/pi/gastrowalogger_env/lib/python3.4/site-packages/flask/app.py", line 1612, in full_dispatch_request
    rv = self.dispatch_request()
  File "/home/pi/gastrowalogger_env/lib/python3.4/site-packages/flask/app.py", line 1598, in dispatch_request
    return self.view_functions[rule.endpoint](**req.view_args)
  File "/home/pi/gastrowalogger_env/gastrowalogger.py", line 590, in calculate_chart
    zeitpunkt_bis += timedelta.seconds(resolution)
TypeError: 'member_descriptor' object is not callable
[2017-10-31 13:52:55 +0100] [4030] [INFO] Handling signal: term
[2017-10-31 13:52:56 +0100] [4039] [INFO] Worker exiting (pid: 4039)
[2017-10-31 13:52:56 +0100] [4030] [INFO] Shutting down: Master
[2017-10-31 13:53:01 +0100] [4246] [INFO] Starting gunicorn 19.7.1
[2017-10-31 13:53:01 +0100] [4246] [INFO] Listening at: http://0.0.0.0:5000 (4246)
[2017-10-31 13:53:01 +0100] [4246] [INFO] Using worker: eventlet
[2017-10-31 13:53:01 +0100] [4269] [INFO] Booting worker with pid: 4269
[2017-10-31 14:02:15 +0100] [4246] [INFO] Handling signal: term
[2017-10-31 14:02:15 +0100] [4269] [INFO] Worker exiting (pid: 4269)
[2017-10-31 14:02:15 +0100] [4246] [INFO] Shutting down: Master
[2017-10-31 14:02:20 +0100] [6732] [INFO] Starting gunicorn 19.7.1
[2017-10-31 14:02:20 +0100] [6732] [INFO] Listening at: http://0.0.0.0:5000 (6732)
[2017-10-31 14:02:20 +0100] [6732] [INFO] Using worker: eventlet
[2017-10-31 14:02:20 +0100] [6752] [INFO] Booting worker with pid: 6752
[2017-10-31 14:19:45 +0100] [6732] [INFO] Handling signal: term
[2017-10-31 14:19:46 +0100] [6752] [INFO] Worker exiting (pid: 6752)
[2017-10-31 14:19:46 +0100] [6732] [INFO] Shutting down: Master
[2017-10-31 14:19:51 +0100] [9712] [INFO] Starting gunicorn 19.7.1
[2017-10-31 14:19:51 +0100] [9712] [INFO] Listening at: http://0.0.0.0:5000 (9712)
[2017-10-31 14:19:51 +0100] [9712] [INFO] Using worker: eventlet
[2017-10-31 14:19:51 +0100] [9717] [INFO] Booting worker with pid: 9717
[2017-10-31 14:19:57,234] ERROR in app: Exception on /charts/_get_chart [POST]
Traceback (most recent call last):
  File "/home/pi/gastrowalogger_env/lib/python3.4/site-packages/flask/app.py", line 1982, in wsgi_app
    response = self.full_dispatch_request()
  File "/home/pi/gastrowalogger_env/lib/python3.4/site-packages/flask/app.py", line 1614, in full_dispatch_request
    rv = self.handle_user_exception(e)
  File "/home/pi/gastrowalogger_env/lib/python3.4/site-packages/flask/app.py", line 1517, in handle_user_exception
    reraise(exc_type, exc_value, tb)
  File "/home/pi/gastrowalogger_env/lib/python3.4/site-packages/flask/_compat.py", line 33, in reraise
    raise value
  File "/home/pi/gastrowalogger_env/lib/python3.4/site-packages/flask/app.py", line 1612, in full_dispatch_request
    rv = self.dispatch_request()
  File "/home/pi/gastrowalogger_env/lib/python3.4/site-packages/flask/app.py", line 1598, in dispatch_request
    return self.view_functions[rule.endpoint](**req.view_args)
  File "/home/pi/gastrowalogger_env/gastrowalogger.py", line 557, in calculate_chart
    for i in range(0, points_count):
TypeError: 'float' object cannot be interpreted as an integer
[2017-10-31 14:19:57,474] ERROR in app: Exception on /charts/_get_chart [POST]
Traceback (most recent call last):
  File "/home/pi/gastrowalogger_env/lib/python3.4/site-packages/flask/app.py", line 1982, in wsgi_app
    response = self.full_dispatch_request()
  File "/home/pi/gastrowalogger_env/lib/python3.4/site-packages/flask/app.py", line 1614, in full_dispatch_request
    rv = self.handle_user_exception(e)
  File "/home/pi/gastrowalogger_env/lib/python3.4/site-packages/flask/app.py", line 1517, in handle_user_exception
    reraise(exc_type, exc_value, tb)
  File "/home/pi/gastrowalogger_env/lib/python3.4/site-packages/flask/_compat.py", line 33, in reraise
    raise value
  File "/home/pi/gastrowalogger_env/lib/python3.4/site-packages/flask/app.py", line 1612, in full_dispatch_request
    rv = self.dispatch_request()
  File "/home/pi/gastrowalogger_env/lib/python3.4/site-packages/flask/app.py", line 1598, in dispatch_request
    return self.view_functions[rule.endpoint](**req.view_args)
  File "/home/pi/gastrowalogger_env/gastrowalogger.py", line 557, in calculate_chart
    for i in range(0, points_count):
TypeError: 'float' object cannot be interpreted as an integer
[2017-10-31 14:20:28 +0100] [9712] [INFO] Handling signal: term
[2017-10-31 14:20:28 +0100] [9717] [INFO] Worker exiting (pid: 9717)
[2017-10-31 14:20:28 +0100] [9712] [INFO] Shutting down: Master
[2017-10-31 14:20:32 +0100] [9748] [INFO] Starting gunicorn 19.7.1
[2017-10-31 14:20:32 +0100] [9748] [INFO] Listening at: http://0.0.0.0:5000 (9748)
[2017-10-31 14:20:32 +0100] [9748] [INFO] Using worker: eventlet
[2017-10-31 14:20:32 +0100] [9751] [INFO] Booting worker with pid: 9751
[2017-10-31 14:22:32 +0100] [9748] [INFO] Handling signal: term
[2017-10-31 14:22:33 +0100] [9751] [INFO] Worker exiting (pid: 9751)
[2017-10-31 14:22:33 +0100] [9748] [INFO] Shutting down: Master
[2017-10-31 14:22:37 +0100] [9805] [INFO] Starting gunicorn 19.7.1
[2017-10-31 14:22:37 +0100] [9805] [INFO] Listening at: http://0.0.0.0:5000 (9805)
[2017-10-31 14:22:37 +0100] [9805] [INFO] Using worker: eventlet
[2017-10-31 14:22:37 +0100] [9809] [INFO] Booting worker with pid: 9809
[2017-10-31 14:24:26 +0100] [9805] [INFO] Handling signal: term
[2017-10-31 14:24:27 +0100] [9809] [INFO] Worker exiting (pid: 9809)
[2017-10-31 14:24:27 +0100] [9805] [INFO] Shutting down: Master
[2017-10-31 14:24:31 +0100] [9893] [INFO] Starting gunicorn 19.7.1
[2017-10-31 14:24:31 +0100] [9893] [INFO] Listening at: http://0.0.0.0:5000 (9893)
[2017-10-31 14:24:31 +0100] [9893] [INFO] Using worker: eventlet
[2017-10-31 14:24:31 +0100] [9896] [INFO] Booting worker with pid: 9896
[2017-10-31 15:43:37 +0100] [9893] [INFO] Handling signal: term
[2017-10-31 15:43:38 +0100] [9896] [INFO] Worker exiting (pid: 9896)
[2017-10-31 15:43:38 +0100] [9893] [INFO] Shutting down: Master
[2017-10-31 15:43:43 +0100] [11636] [INFO] Starting gunicorn 19.7.1
[2017-10-31 15:43:43 +0100] [11636] [INFO] Listening at: http://0.0.0.0:5000 (11636)
[2017-10-31 15:43:43 +0100] [11636] [INFO] Using worker: eventlet
[2017-10-31 15:43:43 +0100] [11639] [INFO] Booting worker with pid: 11639
[2017-10-31 15:45:43 +0100] [11636] [INFO] Handling signal: term
[2017-10-31 15:45:43 +0100] [11639] [INFO] Worker exiting (pid: 11639)
[2017-10-31 15:45:44 +0100] [11636] [INFO] Shutting down: Master
[2017-10-31 15:45:48 +0100] [11700] [INFO] Starting gunicorn 19.7.1
[2017-10-31 15:45:48 +0100] [11700] [INFO] Listening at: http://0.0.0.0:5000 (11700)
[2017-10-31 15:45:48 +0100] [11700] [INFO] Using worker: eventlet
[2017-10-31 15:45:48 +0100] [11703] [INFO] Booting worker with pid: 11703
[2017-10-31 16:00:43 +0100] [11700] [INFO] Handling signal: term
[2017-10-31 16:00:44 +0100] [11703] [INFO] Worker exiting (pid: 11703)
[2017-10-31 16:00:45 +0100] [11700] [INFO] Shutting down: Master
[2017-10-31 16:00:49 +0100] [12015] [INFO] Starting gunicorn 19.7.1
[2017-10-31 16:00:49 +0100] [12015] [INFO] Listening at: http://0.0.0.0:5000 (12015)
[2017-10-31 16:00:49 +0100] [12015] [INFO] Using worker: eventlet
[2017-10-31 16:00:49 +0100] [12020] [INFO] Booting worker with pid: 12020
[2017-10-31 16:37:47 +0100] [12015] [INFO] Handling signal: term
[2017-10-31 16:37:48 +0100] [12020] [INFO] Worker exiting (pid: 12020)
[2017-10-31 16:37:48 +0100] [12015] [INFO] Shutting down: Master
[2017-10-31 16:37:53 +0100] [12757] [INFO] Starting gunicorn 19.7.1
[2017-10-31 16:37:53 +0100] [12757] [INFO] Listening at: http://0.0.0.0:5000 (12757)
[2017-10-31 16:37:53 +0100] [12757] [INFO] Using worker: eventlet
[2017-10-31 16:37:53 +0100] [12760] [INFO] Booting worker with pid: 12760
[2017-10-31 16:37:53 +0100] [12760] [ERROR] invalid syntax (gastrowalogger.py, line 346)
Traceback (most recent call last):
  File "/home/pi/gastrowalogger_env/lib/python3.4/site-packages/gunicorn/workers/base.py", line 135, in load_wsgi
    self.wsgi = self.app.wsgi()
  File "/home/pi/gastrowalogger_env/lib/python3.4/site-packages/gunicorn/app/base.py", line 67, in wsgi
    self.callable = self.load()
  File "/home/pi/gastrowalogger_env/lib/python3.4/site-packages/gunicorn/app/wsgiapp.py", line 65, in load
    return self.load_wsgiapp()
  File "/home/pi/gastrowalogger_env/lib/python3.4/site-packages/gunicorn/app/wsgiapp.py", line 52, in load_wsgiapp
    return util.import_app(self.app_uri)
  File "/home/pi/gastrowalogger_env/lib/python3.4/site-packages/gunicorn/util.py", line 352, in import_app
    __import__(module)
  File "/home/pi/gastrowalogger_env/wsgi.py", line 1, in <module>
    from gastrowalogger import app as application
  File "/home/pi/gastrowalogger_env/gastrowalogger.py", line 346
    cur = db.execute('SELECT amount FROM prices WHERE type = ? ORDER BY timestamp_from DESC', (,sensors[sensor_name]["type"]))
                                                                                               ^
SyntaxError: invalid syntax
[2017-10-31 16:37:53 +0100] [12760] [ERROR] Exception in worker process
Traceback (most recent call last):
  File "/home/pi/gastrowalogger_env/lib/python3.4/site-packages/gunicorn/workers/base.py", line 135, in load_wsgi
    self.wsgi = self.app.wsgi()
  File "/home/pi/gastrowalogger_env/lib/python3.4/site-packages/gunicorn/app/base.py", line 67, in wsgi
    self.callable = self.load()
  File "/home/pi/gastrowalogger_env/lib/python3.4/site-packages/gunicorn/app/wsgiapp.py", line 65, in load
    return self.load_wsgiapp()
  File "/home/pi/gastrowalogger_env/lib/python3.4/site-packages/gunicorn/app/wsgiapp.py", line 52, in load_wsgiapp
    return util.import_app(self.app_uri)
  File "/home/pi/gastrowalogger_env/lib/python3.4/site-packages/gunicorn/util.py", line 352, in import_app
    __import__(module)
  File "/home/pi/gastrowalogger_env/wsgi.py", line 1, in <module>
    from gastrowalogger import app as application
  File "/home/pi/gastrowalogger_env/gastrowalogger.py", line 346
    cur = db.execute('SELECT amount FROM prices WHERE type = ? ORDER BY timestamp_from DESC', (,sensors[sensor_name]["type"]))
                                                                                               ^
SyntaxError: invalid syntax

During handling of the above exception, another exception occurred:

Traceback (most recent call last):
  File "/home/pi/gastrowalogger_env/lib/python3.4/site-packages/gunicorn/arbiter.py", line 578, in spawn_worker
    worker.init_process()
  File "/home/pi/gastrowalogger_env/lib/python3.4/site-packages/gunicorn/workers/geventlet.py", line 103, in init_process
    super(EventletWorker, self).init_process()
  File "/home/pi/gastrowalogger_env/lib/python3.4/site-packages/gunicorn/workers/base.py", line 126, in init_process
    self.load_wsgi()
  File "/home/pi/gastrowalogger_env/lib/python3.4/site-packages/gunicorn/workers/base.py", line 148, in load_wsgi
    self.reloader.add_extra_file(exc_val.filename)
AttributeError: 'NoneType' object has no attribute 'add_extra_file'
[2017-10-31 16:37:53 +0100] [12760] [INFO] Worker exiting (pid: 12760)
[2017-10-31 16:37:54 +0100] [12757] [INFO] Shutting down: Master
[2017-10-31 16:37:54 +0100] [12757] [INFO] Reason: Worker failed to boot.
[2017-10-31 16:39:05 +0100] [12825] [INFO] Starting gunicorn 19.7.1
[2017-10-31 16:39:05 +0100] [12825] [INFO] Listening at: http://0.0.0.0:5000 (12825)
[2017-10-31 16:39:05 +0100] [12825] [INFO] Using worker: eventlet
[2017-10-31 16:39:05 +0100] [12828] [INFO] Booting worker with pid: 12828
[2017-10-31 16:39:05 +0100] [12828] [ERROR] invalid syntax (gastrowalogger.py, line 346)
Traceback (most recent call last):
  File "/home/pi/gastrowalogger_env/lib/python3.4/site-packages/gunicorn/workers/base.py", line 135, in load_wsgi
    self.wsgi = self.app.wsgi()
  File "/home/pi/gastrowalogger_env/lib/python3.4/site-packages/gunicorn/app/base.py", line 67, in wsgi
    self.callable = self.load()
  File "/home/pi/gastrowalogger_env/lib/python3.4/site-packages/gunicorn/app/wsgiapp.py", line 65, in load
    return self.load_wsgiapp()
  File "/home/pi/gastrowalogger_env/lib/python3.4/site-packages/gunicorn/app/wsgiapp.py", line 52, in load_wsgiapp
    return util.import_app(self.app_uri)
  File "/home/pi/gastrowalogger_env/lib/python3.4/site-packages/gunicorn/util.py", line 352, in import_app
    __import__(module)
  File "/home/pi/gastrowalogger_env/wsgi.py", line 1, in <module>
    from gastrowalogger import app as application
  File "/home/pi/gastrowalogger_env/gastrowalogger.py", line 346
    cur = db.execute('SELECT amount FROM prices WHERE type = ? ORDER BY timestamp_from DESC', (,sensors[sensor_name]["type"]))
                                                                                               ^
SyntaxError: invalid syntax
[2017-10-31 16:39:05 +0100] [12828] [ERROR] Exception in worker process
Traceback (most recent call last):
  File "/home/pi/gastrowalogger_env/lib/python3.4/site-packages/gunicorn/workers/base.py", line 135, in load_wsgi
    self.wsgi = self.app.wsgi()
  File "/home/pi/gastrowalogger_env/lib/python3.4/site-packages/gunicorn/app/base.py", line 67, in wsgi
    self.callable = self.load()
  File "/home/pi/gastrowalogger_env/lib/python3.4/site-packages/gunicorn/app/wsgiapp.py", line 65, in load
    return self.load_wsgiapp()
  File "/home/pi/gastrowalogger_env/lib/python3.4/site-packages/gunicorn/app/wsgiapp.py", line 52, in load_wsgiapp
    return util.import_app(self.app_uri)
  File "/home/pi/gastrowalogger_env/lib/python3.4/site-packages/gunicorn/util.py", line 352, in import_app
    __import__(module)
  File "/home/pi/gastrowalogger_env/wsgi.py", line 1, in <module>
    from gastrowalogger import app as application
  File "/home/pi/gastrowalogger_env/gastrowalogger.py", line 346
    cur = db.execute('SELECT amount FROM prices WHERE type = ? ORDER BY timestamp_from DESC', (,sensors[sensor_name]["type"]))
                                                                                               ^
SyntaxError: invalid syntax

During handling of the above exception, another exception occurred:

Traceback (most recent call last):
  File "/home/pi/gastrowalogger_env/lib/python3.4/site-packages/gunicorn/arbiter.py", line 578, in spawn_worker
    worker.init_process()
  File "/home/pi/gastrowalogger_env/lib/python3.4/site-packages/gunicorn/workers/geventlet.py", line 103, in init_process
    super(EventletWorker, self).init_process()
  File "/home/pi/gastrowalogger_env/lib/python3.4/site-packages/gunicorn/workers/base.py", line 126, in init_process
    self.load_wsgi()
  File "/home/pi/gastrowalogger_env/lib/python3.4/site-packages/gunicorn/workers/base.py", line 148, in load_wsgi
    self.reloader.add_extra_file(exc_val.filename)
AttributeError: 'NoneType' object has no attribute 'add_extra_file'
[2017-10-31 16:39:05 +0100] [12828] [INFO] Worker exiting (pid: 12828)
[2017-10-31 16:39:05 +0100] [12825] [INFO] Shutting down: Master
[2017-10-31 16:39:05 +0100] [12825] [INFO] Reason: Worker failed to boot.
[2017-10-31 16:39:45 +0100] [12851] [INFO] Starting gunicorn 19.7.1
[2017-10-31 16:39:45 +0100] [12851] [INFO] Listening at: http://0.0.0.0:5000 (12851)
[2017-10-31 16:39:45 +0100] [12851] [INFO] Using worker: eventlet
[2017-10-31 16:39:45 +0100] [12854] [INFO] Booting worker with pid: 12854
[2017-10-31 16:39:45 +0100] [12854] [ERROR] invalid syntax (gastrowalogger.py, line 346)
Traceback (most recent call last):
  File "/home/pi/gastrowalogger_env/lib/python3.4/site-packages/gunicorn/workers/base.py", line 135, in load_wsgi
    self.wsgi = self.app.wsgi()
  File "/home/pi/gastrowalogger_env/lib/python3.4/site-packages/gunicorn/app/base.py", line 67, in wsgi
    self.callable = self.load()
  File "/home/pi/gastrowalogger_env/lib/python3.4/site-packages/gunicorn/app/wsgiapp.py", line 65, in load
    return self.load_wsgiapp()
  File "/home/pi/gastrowalogger_env/lib/python3.4/site-packages/gunicorn/app/wsgiapp.py", line 52, in load_wsgiapp
    return util.import_app(self.app_uri)
  File "/home/pi/gastrowalogger_env/lib/python3.4/site-packages/gunicorn/util.py", line 352, in import_app
    __import__(module)
  File "/home/pi/gastrowalogger_env/wsgi.py", line 1, in <module>
    from gastrowalogger import app as application
  File "/home/pi/gastrowalogger_env/gastrowalogger.py", line 346
    cur = db.execute('SELECT amount FROM prices WHERE type = ? ORDER BY timestamp_from DESC', (,sensors[sensor_name]["type"]))
                                                                                               ^
SyntaxError: invalid syntax
[2017-10-31 16:39:45 +0100] [12854] [ERROR] Exception in worker process
Traceback (most recent call last):
  File "/home/pi/gastrowalogger_env/lib/python3.4/site-packages/gunicorn/workers/base.py", line 135, in load_wsgi
    self.wsgi = self.app.wsgi()
  File "/home/pi/gastrowalogger_env/lib/python3.4/site-packages/gunicorn/app/base.py", line 67, in wsgi
    self.callable = self.load()
  File "/home/pi/gastrowalogger_env/lib/python3.4/site-packages/gunicorn/app/wsgiapp.py", line 65, in load
    return self.load_wsgiapp()
  File "/home/pi/gastrowalogger_env/lib/python3.4/site-packages/gunicorn/app/wsgiapp.py", line 52, in load_wsgiapp
    return util.import_app(self.app_uri)
  File "/home/pi/gastrowalogger_env/lib/python3.4/site-packages/gunicorn/util.py", line 352, in import_app
    __import__(module)
  File "/home/pi/gastrowalogger_env/wsgi.py", line 1, in <module>
    from gastrowalogger import app as application
  File "/home/pi/gastrowalogger_env/gastrowalogger.py", line 346
    cur = db.execute('SELECT amount FROM prices WHERE type = ? ORDER BY timestamp_from DESC', (,sensors[sensor_name]["type"]))
                                                                                               ^
SyntaxError: invalid syntax

During handling of the above exception, another exception occurred:

Traceback (most recent call last):
  File "/home/pi/gastrowalogger_env/lib/python3.4/site-packages/gunicorn/arbiter.py", line 578, in spawn_worker
    worker.init_process()
  File "/home/pi/gastrowalogger_env/lib/python3.4/site-packages/gunicorn/workers/geventlet.py", line 103, in init_process
    super(EventletWorker, self).init_process()
  File "/home/pi/gastrowalogger_env/lib/python3.4/site-packages/gunicorn/workers/base.py", line 126, in init_process
    self.load_wsgi()
  File "/home/pi/gastrowalogger_env/lib/python3.4/site-packages/gunicorn/workers/base.py", line 148, in load_wsgi
    self.reloader.add_extra_file(exc_val.filename)
AttributeError: 'NoneType' object has no attribute 'add_extra_file'
[2017-10-31 16:39:45 +0100] [12854] [INFO] Worker exiting (pid: 12854)
[2017-10-31 16:39:45 +0100] [12851] [INFO] Shutting down: Master
[2017-10-31 16:39:45 +0100] [12851] [INFO] Reason: Worker failed to boot.
[2017-10-31 16:40:51 +0100] [12878] [INFO] Starting gunicorn 19.7.1
[2017-10-31 16:40:51 +0100] [12878] [INFO] Listening at: http://0.0.0.0:5000 (12878)
[2017-10-31 16:40:51 +0100] [12878] [INFO] Using worker: eventlet
[2017-10-31 16:40:51 +0100] [12881] [INFO] Booting worker with pid: 12881
[2017-10-31 16:41:07,030] ERROR in app: Exception on /sensor/current [GET]
Traceback (most recent call last):
  File "/home/pi/gastrowalogger_env/lib/python3.4/site-packages/flask/app.py", line 1982, in wsgi_app
    response = self.full_dispatch_request()
  File "/home/pi/gastrowalogger_env/lib/python3.4/site-packages/flask/app.py", line 1614, in full_dispatch_request
    rv = self.handle_user_exception(e)
  File "/home/pi/gastrowalogger_env/lib/python3.4/site-packages/flask/app.py", line 1517, in handle_user_exception
    reraise(exc_type, exc_value, tb)
  File "/home/pi/gastrowalogger_env/lib/python3.4/site-packages/flask/_compat.py", line 33, in reraise
    raise value
  File "/home/pi/gastrowalogger_env/lib/python3.4/site-packages/flask/app.py", line 1612, in full_dispatch_request
    rv = self.dispatch_request()
  File "/home/pi/gastrowalogger_env/lib/python3.4/site-packages/flask/app.py", line 1598, in dispatch_request
    return self.view_functions[rule.endpoint](**req.view_args)
  File "/home/pi/gastrowalogger_env/gastrowalogger.py", line 346, in wasserverbrauch
    cur = db.execute('SELECT amount FROM prices WHERE type = ? ORDER BY timestamp_from DESC', (types[sensors[sensor_name]["type"]],))
KeyError: None
[2017-10-31 16:41:50 +0100] [12878] [INFO] Handling signal: term
[2017-10-31 16:41:50 +0100] [12881] [INFO] Worker exiting (pid: 12881)
[2017-10-31 16:41:51 +0100] [12878] [INFO] Shutting down: Master
[2017-10-31 16:41:55 +0100] [12937] [INFO] Starting gunicorn 19.7.1
[2017-10-31 16:41:55 +0100] [12937] [INFO] Listening at: http://0.0.0.0:5000 (12937)
[2017-10-31 16:41:55 +0100] [12937] [INFO] Using worker: eventlet
[2017-10-31 16:41:55 +0100] [12940] [INFO] Booting worker with pid: 12940
[2017-10-31 16:42:24 +0100] [12937] [INFO] Handling signal: term
[2017-10-31 16:42:25 +0100] [12940] [INFO] Worker exiting (pid: 12940)
[2017-10-31 16:42:26 +0100] [12937] [INFO] Shutting down: Master
[2017-10-31 16:42:30 +0100] [12962] [INFO] Starting gunicorn 19.7.1
[2017-10-31 16:42:30 +0100] [12962] [INFO] Listening at: http://0.0.0.0:5000 (12962)
[2017-10-31 16:42:30 +0100] [12962] [INFO] Using worker: eventlet
[2017-10-31 16:42:30 +0100] [12965] [INFO] Booting worker with pid: 12965
[2017-10-31 16:46:13 +0100] [12962] [INFO] Handling signal: term
[2017-10-31 16:46:43 +0100] [12962] [INFO] Shutting down: Master
[2017-10-31 16:46:47 +0100] [13106] [INFO] Starting gunicorn 19.7.1
[2017-10-31 16:46:47 +0100] [13106] [INFO] Listening at: http://0.0.0.0:5000 (13106)
[2017-10-31 16:46:47 +0100] [13106] [INFO] Using worker: eventlet
[2017-10-31 16:46:47 +0100] [13115] [INFO] Booting worker with pid: 13115
